<?xml version="1.0"?>
<robot name="unmanned_vehicle" xmlns:xacro="http://www.ros.org/wiki/xacro">

  <xacro:property name="M_PI" value="3.1415926535897931" />

  <link name="base_link">
    <visual>
      <geometry>
        <box size="0.8 0.5 0.3"/>
      </geometry>
      <material name="gray">
        <color rgba="0.5 0.5 0.5 1"/>
      </material>
    </visual>
    <collision>
      <geometry>
        <box size="0.8 0.5 0.3"/>
      </geometry>
    </collision>
    <inertial>
      <mass value="20"/>
      <inertia ixx="1.0" ixy="0.0" ixz="0.0" iyy="1.0" iyz="0.0" izz="1.0"/>
    </inertial>
  </link>

  <xacro:macro name="wheel" params="prefix reflect">
    <joint name="${prefix}_wheel_joint" type="continuous">
      <parent link="base_link"/>
      <child link="${prefix}_wheel"/>
      <origin xyz="0.3 ${reflect*0.25} 0" rpy="0 0 0"/>
      <axis xyz="0 1 0"/>
    </joint>

    <link name="${prefix}_wheel">
      <visual>
        <geometry>
          <cylinder radius="0.15" length="0.1"/>
        </geometry>
        <material name="black">
          <color rgba="0 0 0 1"/>
        </material>
      </visual>
      <collision>
        <geometry>
          <cylinder radius="0.15" length="0.1"/>
        </geometry>
      </collision>
      <inertial>
        <mass value="1"/>
        <inertia ixx="0.01" ixy="0.0" ixz="0.0" iyy="0.01" iyz="0.0" izz="0.01"/>
      </inertial>
    </link>
  </xacro:macro>

  <xacro:wheel prefix="front_left" reflect="1" />
  <xacro:wheel prefix="front_right" reflect="-1" />
  <xacro:wheel prefix="rear_left" reflect="1" />
  <xacro:wheel prefix="rear_right" reflect="-1" />

  <link name="camera_link">
    <visual>
      <geometry>
        <box size="0.05 0.1 0.05"/>
      </geometry>
      <material name="red">
        <color rgba="1 0 0 1"/>
      </material>
    </visual>
  </link>

  <joint name="camera_joint" type="fixed">
    <parent link="base_link"/>
    <child link="camera_link"/>
    <origin xyz="0.4 0 0.1" rpy="0 0 0"/>
  </joint>

</robot>


